{"timestamp": "2025-08-31T11:26:32.870549", "level": "ERROR", "message": "Exception on /quiz/choix [GET]", "module": "app", "function": "log_exception", "line": 875, "request_id": "1756639592.595614_51617", "user_id": null, "ip": "127.0.0.1", "method": "GET", "url": "http://127.0.0.1:5000/quiz/choix?quiz_type=public", "user_agent": "Mozilla/5.0 (Macintosh; Intel Mac OS X 10_15_7) AppleWebKit/537.36 (KHTML, like Gecko) Chrome/139.0.0.0 Safari/537.36", "exception": {"type": "IndexError", "message": "tuple index out of range", "traceback": ["Traceback (most recent call last):\n", "  File \"/Library/Frameworks/Python.framework/Versions/3.13/lib/python3.13/site-packages/flask/app.py\", line 1511, in wsgi_app\n    response = self.full_dispatch_request()\n", "  File \"/Library/Frameworks/Python.framework/Versions/3.13/lib/python3.13/site-packages/flask/app.py\", line 919, in full_dispatch_request\n    rv = self.handle_user_exception(e)\n", "  File \"/Library/Frameworks/Python.framework/Versions/3.13/lib/python3.13/site-packages/flask_cors/extension.py\", line 176, in wrapped_function\n    return cors_after_request(app.make_response(f(*args, **kwargs)))\n                                                ~^^^^^^^^^^^^^^^^^\n", "  File \"/Library/Frameworks/Python.framework/Versions/3.13/lib/python3.13/site-packages/flask/app.py\", line 917, in full_dispatch_request\n    rv = self.dispatch_request()\n", "  File \"/Library/Frameworks/Python.framework/Versions/3.13/lib/python3.13/site-packages/flask/app.py\", line 902, in dispatch_request\n    return self.ensure_sync(self.view_functions[rule.endpoint])(**view_args)  # type: ignore[no-any-return]\n           ~~~~~~~~~~~~~~~~~~~~~~~~~~~~~~~~~~~~~~~~~~~~~~~~~~~~^^^^^^^^^^^^^\n", "  File \"/Users/tchicayadivin/project/quiz/routes.py\", line 48, in choix\n    dossiers = [{\"titre\": row[0], \"user_id\": row[1], \"matiere\": row[2],\n                                                                ~~~^^^\n", "IndexError: tuple index out of range\n"]}}
{"timestamp": "2025-08-31T11:26:32.872776", "level": "ERROR", "message": "500 Error: 500 Internal Server Error: The server encountered an internal error and was unable to complete your request. Either the server is overloaded or there is an error in the application.", "module": "monitoring", "function": "internal_error", "line": 237, "request_id": "1756639592.595614_51617", "user_id": null, "ip": "127.0.0.1", "method": "GET", "url": "http://127.0.0.1:5000/quiz/choix?quiz_type=public", "user_agent": "Mozilla/5.0 (Macintosh; Intel Mac OS X 10_15_7) AppleWebKit/537.36 (KHTML, like Gecko) Chrome/139.0.0.0 Safari/537.36", "exception": {"type": "IndexError", "message": "tuple index out of range", "traceback": ["Traceback (most recent call last):\n", "  File \"/Library/Frameworks/Python.framework/Versions/3.13/lib/python3.13/site-packages/flask/app.py\", line 1511, in wsgi_app\n    response = self.full_dispatch_request()\n", "  File \"/Library/Frameworks/Python.framework/Versions/3.13/lib/python3.13/site-packages/flask/app.py\", line 919, in full_dispatch_request\n    rv = self.handle_user_exception(e)\n", "  File \"/Library/Frameworks/Python.framework/Versions/3.13/lib/python3.13/site-packages/flask_cors/extension.py\", line 176, in wrapped_function\n    return cors_after_request(app.make_response(f(*args, **kwargs)))\n                                                ~^^^^^^^^^^^^^^^^^\n", "  File \"/Library/Frameworks/Python.framework/Versions/3.13/lib/python3.13/site-packages/flask/app.py\", line 917, in full_dispatch_request\n    rv = self.dispatch_request()\n", "  File \"/Library/Frameworks/Python.framework/Versions/3.13/lib/python3.13/site-packages/flask/app.py\", line 902, in dispatch_request\n    return self.ensure_sync(self.view_functions[rule.endpoint])(**view_args)  # type: ignore[no-any-return]\n           ~~~~~~~~~~~~~~~~~~~~~~~~~~~~~~~~~~~~~~~~~~~~~~~~~~~~^^^^^^^^^^^^^\n", "  File \"/Users/tchicayadivin/project/quiz/routes.py\", line 48, in choix\n    dossiers = [{\"titre\": row[0], \"user_id\": row[1], \"matiere\": row[2],\n                                                                ~~~^^^\n", "IndexError: tuple index out of range\n"]}}
{"timestamp": "2025-08-31T11:29:12.249199", "level": "ERROR", "message": "Exception on /quiz/choix [GET]", "module": "app", "function": "log_exception", "line": 875, "request_id": "1756639752.0439548_52243", "user_id": 1, "ip": "127.0.0.1", "method": "GET", "url": "http://127.0.0.1:5000/quiz/choix?quiz_type=public", "user_agent": "Mozilla/5.0 (Macintosh; Intel Mac OS X 10_15_7) AppleWebKit/537.36 (KHTML, like Gecko) Chrome/139.0.0.0 Safari/537.36", "exception": {"type": "IndexError", "message": "tuple index out of range", "traceback": ["Traceback (most recent call last):\n", "  File \"/Library/Frameworks/Python.framework/Versions/3.13/lib/python3.13/site-packages/flask/app.py\", line 1511, in wsgi_app\n    response = self.full_dispatch_request()\n", "  File \"/Library/Frameworks/Python.framework/Versions/3.13/lib/python3.13/site-packages/flask/app.py\", line 919, in full_dispatch_request\n    rv = self.handle_user_exception(e)\n", "  File \"/Library/Frameworks/Python.framework/Versions/3.13/lib/python3.13/site-packages/flask_cors/extension.py\", line 176, in wrapped_function\n    return cors_after_request(app.make_response(f(*args, **kwargs)))\n                                                ~^^^^^^^^^^^^^^^^^\n", "  File \"/Library/Frameworks/Python.framework/Versions/3.13/lib/python3.13/site-packages/flask/app.py\", line 917, in full_dispatch_request\n    rv = self.dispatch_request()\n", "  File \"/Library/Frameworks/Python.framework/Versions/3.13/lib/python3.13/site-packages/flask/app.py\", line 902, in dispatch_request\n    return self.ensure_sync(self.view_functions[rule.endpoint])(**view_args)  # type: ignore[no-any-return]\n           ~~~~~~~~~~~~~~~~~~~~~~~~~~~~~~~~~~~~~~~~~~~~~~~~~~~~^^^^^^^^^^^^^\n", "  File \"/Users/tchicayadivin/project/quiz/routes.py\", line 48, in choix\n    dossiers = [{\"titre\": row[0], \"user_id\": row[1], \"matiere\": row[2],\n                                                                ~~~^^^\n", "IndexError: tuple index out of range\n"]}}
{"timestamp": "2025-08-31T11:29:12.252369", "level": "ERROR", "message": "500 Error: 500 Internal Server Error: The server encountered an internal error and was unable to complete your request. Either the server is overloaded or there is an error in the application.", "module": "monitoring", "function": "internal_error", "line": 237, "request_id": "1756639752.0439548_52243", "user_id": 1, "ip": "127.0.0.1", "method": "GET", "url": "http://127.0.0.1:5000/quiz/choix?quiz_type=public", "user_agent": "Mozilla/5.0 (Macintosh; Intel Mac OS X 10_15_7) AppleWebKit/537.36 (KHTML, like Gecko) Chrome/139.0.0.0 Safari/537.36", "exception": {"type": "IndexError", "message": "tuple index out of range", "traceback": ["Traceback (most recent call last):\n", "  File \"/Library/Frameworks/Python.framework/Versions/3.13/lib/python3.13/site-packages/flask/app.py\", line 1511, in wsgi_app\n    response = self.full_dispatch_request()\n", "  File \"/Library/Frameworks/Python.framework/Versions/3.13/lib/python3.13/site-packages/flask/app.py\", line 919, in full_dispatch_request\n    rv = self.handle_user_exception(e)\n", "  File \"/Library/Frameworks/Python.framework/Versions/3.13/lib/python3.13/site-packages/flask_cors/extension.py\", line 176, in wrapped_function\n    return cors_after_request(app.make_response(f(*args, **kwargs)))\n                                                ~^^^^^^^^^^^^^^^^^\n", "  File \"/Library/Frameworks/Python.framework/Versions/3.13/lib/python3.13/site-packages/flask/app.py\", line 917, in full_dispatch_request\n    rv = self.dispatch_request()\n", "  File \"/Library/Frameworks/Python.framework/Versions/3.13/lib/python3.13/site-packages/flask/app.py\", line 902, in dispatch_request\n    return self.ensure_sync(self.view_functions[rule.endpoint])(**view_args)  # type: ignore[no-any-return]\n           ~~~~~~~~~~~~~~~~~~~~~~~~~~~~~~~~~~~~~~~~~~~~~~~~~~~~^^^^^^^^^^^^^\n", "  File \"/Users/tchicayadivin/project/quiz/routes.py\", line 48, in choix\n    dossiers = [{\"titre\": row[0], \"user_id\": row[1], \"matiere\": row[2],\n                                                                ~~~^^^\n", "IndexError: tuple index out of range\n"]}}
{"timestamp": "2025-08-31T13:38:20.749402", "level": "ERROR", "message": "Exception on /quiz/choix [GET]", "module": "app", "function": "log_exception", "line": 875, "request_id": "1756647500.324824_66277", "user_id": 1, "ip": "127.0.0.1", "method": "GET", "url": "http://127.0.0.1:5000/quiz/choix?quiz_type=public", "user_agent": "Mozilla/5.0 (Macintosh; Intel Mac OS X 10_15_7) AppleWebKit/537.36 (KHTML, like Gecko) Chrome/139.0.0.0 Safari/537.36", "exception": {"type": "IndexError", "message": "tuple index out of range", "traceback": ["Traceback (most recent call last):\n", "  File \"/Library/Frameworks/Python.framework/Versions/3.13/lib/python3.13/site-packages/flask/app.py\", line 1511, in wsgi_app\n    response = self.full_dispatch_request()\n", "  File \"/Library/Frameworks/Python.framework/Versions/3.13/lib/python3.13/site-packages/flask/app.py\", line 919, in full_dispatch_request\n    rv = self.handle_user_exception(e)\n", "  File \"/Library/Frameworks/Python.framework/Versions/3.13/lib/python3.13/site-packages/flask_cors/extension.py\", line 176, in wrapped_function\n    return cors_after_request(app.make_response(f(*args, **kwargs)))\n                                                ~^^^^^^^^^^^^^^^^^\n", "  File \"/Library/Frameworks/Python.framework/Versions/3.13/lib/python3.13/site-packages/flask/app.py\", line 917, in full_dispatch_request\n    rv = self.dispatch_request()\n", "  File \"/Library/Frameworks/Python.framework/Versions/3.13/lib/python3.13/site-packages/flask/app.py\", line 902, in dispatch_request\n    return self.ensure_sync(self.view_functions[rule.endpoint])(**view_args)  # type: ignore[no-any-return]\n           ~~~~~~~~~~~~~~~~~~~~~~~~~~~~~~~~~~~~~~~~~~~~~~~~~~~~^^^^^^^^^^^^^\n", "  File \"/Users/tchicayadivin/project/quiz/routes.py\", line 49, in choix\n    dossiers = [{\"titre\": row[0], \"user_id\": row[1], \"matiere\": row[2],\n                                                                ~~~^^^\n", "IndexError: tuple index out of range\n"]}}
{"timestamp": "2025-08-31T13:38:20.752072", "level": "ERROR", "message": "500 Error: 500 Internal Server Error: The server encountered an internal error and was unable to complete your request. Either the server is overloaded or there is an error in the application.", "module": "monitoring", "function": "internal_error", "line": 237, "request_id": "1756647500.324824_66277", "user_id": 1, "ip": "127.0.0.1", "method": "GET", "url": "http://127.0.0.1:5000/quiz/choix?quiz_type=public", "user_agent": "Mozilla/5.0 (Macintosh; Intel Mac OS X 10_15_7) AppleWebKit/537.36 (KHTML, like Gecko) Chrome/139.0.0.0 Safari/537.36", "exception": {"type": "IndexError", "message": "tuple index out of range", "traceback": ["Traceback (most recent call last):\n", "  File \"/Library/Frameworks/Python.framework/Versions/3.13/lib/python3.13/site-packages/flask/app.py\", line 1511, in wsgi_app\n    response = self.full_dispatch_request()\n", "  File \"/Library/Frameworks/Python.framework/Versions/3.13/lib/python3.13/site-packages/flask/app.py\", line 919, in full_dispatch_request\n    rv = self.handle_user_exception(e)\n", "  File \"/Library/Frameworks/Python.framework/Versions/3.13/lib/python3.13/site-packages/flask_cors/extension.py\", line 176, in wrapped_function\n    return cors_after_request(app.make_response(f(*args, **kwargs)))\n                                                ~^^^^^^^^^^^^^^^^^\n", "  File \"/Library/Frameworks/Python.framework/Versions/3.13/lib/python3.13/site-packages/flask/app.py\", line 917, in full_dispatch_request\n    rv = self.dispatch_request()\n", "  File \"/Library/Frameworks/Python.framework/Versions/3.13/lib/python3.13/site-packages/flask/app.py\", line 902, in dispatch_request\n    return self.ensure_sync(self.view_functions[rule.endpoint])(**view_args)  # type: ignore[no-any-return]\n           ~~~~~~~~~~~~~~~~~~~~~~~~~~~~~~~~~~~~~~~~~~~~~~~~~~~~^^^^^^^^^^^^^\n", "  File \"/Users/tchicayadivin/project/quiz/routes.py\", line 49, in choix\n    dossiers = [{\"titre\": row[0], \"user_id\": row[1], \"matiere\": row[2],\n                                                                ~~~^^^\n", "IndexError: tuple index out of range\n"]}}
{"timestamp": "2025-08-31T16:22:42.091229", "level": "ERROR", "message": "Exception on /quiz/choix [GET]", "module": "app", "function": "log_exception", "line": 875, "request_id": "1756657361.8357298_66277", "user_id": 1, "ip": "127.0.0.1", "method": "GET", "url": "http://127.0.0.1:5000/quiz/choix?quiz_type=public", "user_agent": "Mozilla/5.0 (Macintosh; Intel Mac OS X 10_15_7) AppleWebKit/537.36 (KHTML, like Gecko) Chrome/139.0.0.0 Safari/537.36", "exception": {"type": "IndexError", "message": "tuple index out of range", "traceback": ["Traceback (most recent call last):\n", "  File \"/Library/Frameworks/Python.framework/Versions/3.13/lib/python3.13/site-packages/flask/app.py\", line 1511, in wsgi_app\n    response = self.full_dispatch_request()\n", "  File \"/Library/Frameworks/Python.framework/Versions/3.13/lib/python3.13/site-packages/flask/app.py\", line 919, in full_dispatch_request\n    rv = self.handle_user_exception(e)\n", "  File \"/Library/Frameworks/Python.framework/Versions/3.13/lib/python3.13/site-packages/flask_cors/extension.py\", line 176, in wrapped_function\n    return cors_after_request(app.make_response(f(*args, **kwargs)))\n                                                ~^^^^^^^^^^^^^^^^^\n", "  File \"/Library/Frameworks/Python.framework/Versions/3.13/lib/python3.13/site-packages/flask/app.py\", line 917, in full_dispatch_request\n    rv = self.dispatch_request()\n", "  File \"/Library/Frameworks/Python.framework/Versions/3.13/lib/python3.13/site-packages/flask/app.py\", line 902, in dispatch_request\n    return self.ensure_sync(self.view_functions[rule.endpoint])(**view_args)  # type: ignore[no-any-return]\n           ~~~~~~~~~~~~~~~~~~~~~~~~~~~~~~~~~~~~~~~~~~~~~~~~~~~~^^^^^^^^^^^^^\n", "  File \"/Users/tchicayadivin/project/quiz/routes.py\", line 49, in choix\n    LIMIT 10 OFFSET %s\n    \n", "IndexError: tuple index out of range\n"]}}
{"timestamp": "2025-08-31T16:22:42.093359", "level": "ERROR", "message": "500 Error: 500 Internal Server Error: The server encountered an internal error and was unable to complete your request. Either the server is overloaded or there is an error in the application.", "module": "monitoring", "function": "internal_error", "line": 237, "request_id": "1756657361.8357298_66277", "user_id": 1, "ip": "127.0.0.1", "method": "GET", "url": "http://127.0.0.1:5000/quiz/choix?quiz_type=public", "user_agent": "Mozilla/5.0 (Macintosh; Intel Mac OS X 10_15_7) AppleWebKit/537.36 (KHTML, like Gecko) Chrome/139.0.0.0 Safari/537.36", "exception": {"type": "IndexError", "message": "tuple index out of range", "traceback": ["Traceback (most recent call last):\n", "  File \"/Library/Frameworks/Python.framework/Versions/3.13/lib/python3.13/site-packages/flask/app.py\", line 1511, in wsgi_app\n    response = self.full_dispatch_request()\n", "  File \"/Library/Frameworks/Python.framework/Versions/3.13/lib/python3.13/site-packages/flask/app.py\", line 919, in full_dispatch_request\n    rv = self.handle_user_exception(e)\n", "  File \"/Library/Frameworks/Python.framework/Versions/3.13/lib/python3.13/site-packages/flask_cors/extension.py\", line 176, in wrapped_function\n    return cors_after_request(app.make_response(f(*args, **kwargs)))\n                                                ~^^^^^^^^^^^^^^^^^\n", "  File \"/Library/Frameworks/Python.framework/Versions/3.13/lib/python3.13/site-packages/flask/app.py\", line 917, in full_dispatch_request\n    rv = self.dispatch_request()\n", "  File \"/Library/Frameworks/Python.framework/Versions/3.13/lib/python3.13/site-packages/flask/app.py\", line 902, in dispatch_request\n    return self.ensure_sync(self.view_functions[rule.endpoint])(**view_args)  # type: ignore[no-any-return]\n           ~~~~~~~~~~~~~~~~~~~~~~~~~~~~~~~~~~~~~~~~~~~~~~~~~~~~^^^^^^^^^^^^^\n", "  File \"/Users/tchicayadivin/project/quiz/routes.py\", line 49, in choix\n    LIMIT 10 OFFSET %s\n    \n", "IndexError: tuple index out of range\n"]}}
